~/gold-investment-backend$ python -m pytest tests/ -v --disable-warnings
========================================== test session starts ==========================================
platform linux -- Python 3.11.10, pytest-7.4.3, pluggy-1.5.0 -- /home/runner/gold-investment-backend/.pythonlibs/bin/python
cachedir: .pytest_cache
rootdir: /home/runner/gold-investment-backend/tests
configfile: pytest.ini
plugins: mock-3.12.0, asyncio-0.21.1, web3-6.11.3
asyncio: mode=Mode.AUTO
collected 6 items                                                                                       

tests/test_blockchain.py::test_blockchain_connection ERROR                                        [ 16%]
tests/test_blockchain.py::test_noble_rank_update ERROR                                            [ 33%]
tests/test_noble_system.py::test_noble_rank_creation ERROR                                        [ 50%]
tests/test_noble_system.py::test_noble_relation_verification ERROR                                [ 66%]
tests/test_transformation.py::test_gold_transformation ERROR                                      [ 83%]
tests/test_transformation.py::test_minimum_transformation_amount ERROR                            [100%]

================================================ ERRORS =================================================
_____________________________ ERROR at setup of test_blockchain_connection ______________________________
.pythonlibs/lib/python3.11/site-packages/pytest_asyncio/plugin.py:304: in _asyncgen_fixture_wrapper
    result = event_loop.run_until_complete(setup())
/nix/store/clx0mcir7qw8zk36zbr4jra789g3knf6-python3-3.11.10/lib/python3.11/asyncio/base_events.py:654: in run_until_complete
    return future.result()
.pythonlibs/lib/python3.11/site-packages/pytest_asyncio/plugin.py:286: in setup
    res = await gen_obj.__anext__()
tests/conftest.py:17: in app
    app = create_app()
app/__init__.py:87: in create_app
    db.drop_all()
.pythonlibs/lib/python3.11/site-packages/flask_sqlalchemy/extension.py:917: in drop_all
    self._call_for_binds(bind_key, "drop_all")
.pythonlibs/lib/python3.11/site-packages/flask_sqlalchemy/extension.py:881: in _call_for_binds
    getattr(metadata, op_name)(bind=engine)
.pythonlibs/lib/python3.11/site-packages/sqlalchemy/sql/schema.py:5856: in drop_all
    bind._run_ddl_visitor(
.pythonlibs/lib/python3.11/site-packages/sqlalchemy/engine/base.py:3243: in _run_ddl_visitor
    conn._run_ddl_visitor(visitorcallable, element, **kwargs)
.pythonlibs/lib/python3.11/site-packages/sqlalchemy/engine/base.py:2447: in _run_ddl_visitor
    visitorcallable(self.dialect, self, **kwargs).traverse_single(element)
.pythonlibs/lib/python3.11/site-packages/sqlalchemy/sql/visitors.py:671: in traverse_single
    return meth(obj, **kw)
.pythonlibs/lib/python3.11/site-packages/sqlalchemy/sql/ddl.py:1022: in visit_metadata
    sort_tables_and_constraints(
.pythonlibs/lib/python3.11/site-packages/sqlalchemy/sql/ddl.py:1327: in sort_tables_and_constraints
    dependent_on = fkc.referred_table
.pythonlibs/lib/python3.11/site-packages/sqlalchemy/sql/schema.py:4751: in referred_table
    return self.elements[0].column.table
.pythonlibs/lib/python3.11/site-packages/sqlalchemy/util/langhelpers.py:1146: in __get__
    obj.__dict__[self.__name__] = result = self.fget(obj)
.pythonlibs/lib/python3.11/site-packages/sqlalchemy/sql/schema.py:3159: in column
    return self._resolve_column()
.pythonlibs/lib/python3.11/site-packages/sqlalchemy/sql/schema.py:3182: in _resolve_column
    raise exc.NoReferencedTableError(
E   sqlalchemy.exc.NoReferencedTableError: Foreign key associated with column 'bonus_transactions.user_id' could not find table 'users' with which to generate a foreign key to target column 'id'
_______________________________ ERROR at setup of test_noble_rank_update ________________________________
.pythonlibs/lib/python3.11/site-packages/pytest_asyncio/plugin.py:304: in _asyncgen_fixture_wrapper
    result = event_loop.run_until_complete(setup())
/nix/store/clx0mcir7qw8zk36zbr4jra789g3knf6-python3-3.11.10/lib/python3.11/asyncio/base_events.py:654: in run_until_complete
    return future.result()
.pythonlibs/lib/python3.11/site-packages/pytest_asyncio/plugin.py:286: in setup
    res = await gen_obj.__anext__()
tests/conftest.py:17: in app
    app = create_app()
app/__init__.py:87: in create_app
    db.drop_all()
.pythonlibs/lib/python3.11/site-packages/flask_sqlalchemy/extension.py:917: in drop_all
    self._call_for_binds(bind_key, "drop_all")
.pythonlibs/lib/python3.11/site-packages/flask_sqlalchemy/extension.py:881: in _call_for_binds
    getattr(metadata, op_name)(bind=engine)
.pythonlibs/lib/python3.11/site-packages/sqlalchemy/sql/schema.py:5856: in drop_all
    bind._run_ddl_visitor(
.pythonlibs/lib/python3.11/site-packages/sqlalchemy/engine/base.py:3243: in _run_ddl_visitor
    conn._run_ddl_visitor(visitorcallable, element, **kwargs)
.pythonlibs/lib/python3.11/site-packages/sqlalchemy/engine/base.py:2447: in _run_ddl_visitor
    visitorcallable(self.dialect, self, **kwargs).traverse_single(element)
.pythonlibs/lib/python3.11/site-packages/sqlalchemy/sql/visitors.py:671: in traverse_single
    return meth(obj, **kw)
.pythonlibs/lib/python3.11/site-packages/sqlalchemy/sql/ddl.py:1022: in visit_metadata
    sort_tables_and_constraints(
.pythonlibs/lib/python3.11/site-packages/sqlalchemy/sql/ddl.py:1327: in sort_tables_and_constraints
    dependent_on = fkc.referred_table
.pythonlibs/lib/python3.11/site-packages/sqlalchemy/sql/schema.py:4751: in referred_table
    return self.elements[0].column.table
.pythonlibs/lib/python3.11/site-packages/sqlalchemy/util/langhelpers.py:1146: in __get__
    obj.__dict__[self.__name__] = result = self.fget(obj)
.pythonlibs/lib/python3.11/site-packages/sqlalchemy/sql/schema.py:3159: in column
    return self._resolve_column()
.pythonlibs/lib/python3.11/site-packages/sqlalchemy/sql/schema.py:3182: in _resolve_column
    raise exc.NoReferencedTableError(
E   sqlalchemy.exc.NoReferencedTableError: Foreign key associated with column 'bonus_transactions.user_id' could not find table 'users' with which to generate a foreign key to target column 'id'
______________________________ ERROR at setup of test_noble_rank_creation _______________________________
.pythonlibs/lib/python3.11/site-packages/pytest_asyncio/plugin.py:304: in _asyncgen_fixture_wrapper
    result = event_loop.run_until_complete(setup())
/nix/store/clx0mcir7qw8zk36zbr4jra789g3knf6-python3-3.11.10/lib/python3.11/asyncio/base_events.py:654: in run_until_complete
    return future.result()
.pythonlibs/lib/python3.11/site-packages/pytest_asyncio/plugin.py:286: in setup
    res = await gen_obj.__anext__()
tests/conftest.py:17: in app
    app = create_app()
app/__init__.py:87: in create_app
    db.drop_all()
.pythonlibs/lib/python3.11/site-packages/flask_sqlalchemy/extension.py:917: in drop_all
    self._call_for_binds(bind_key, "drop_all")
.pythonlibs/lib/python3.11/site-packages/flask_sqlalchemy/extension.py:881: in _call_for_binds
    getattr(metadata, op_name)(bind=engine)
.pythonlibs/lib/python3.11/site-packages/sqlalchemy/sql/schema.py:5856: in drop_all
    bind._run_ddl_visitor(
.pythonlibs/lib/python3.11/site-packages/sqlalchemy/engine/base.py:3243: in _run_ddl_visitor
    conn._run_ddl_visitor(visitorcallable, element, **kwargs)
.pythonlibs/lib/python3.11/site-packages/sqlalchemy/engine/base.py:2447: in _run_ddl_visitor
    visitorcallable(self.dialect, self, **kwargs).traverse_single(element)
.pythonlibs/lib/python3.11/site-packages/sqlalchemy/sql/visitors.py:671: in traverse_single
    return meth(obj, **kw)
.pythonlibs/lib/python3.11/site-packages/sqlalchemy/sql/ddl.py:1022: in visit_metadata
    sort_tables_and_constraints(
.pythonlibs/lib/python3.11/site-packages/sqlalchemy/sql/ddl.py:1327: in sort_tables_and_constraints
    dependent_on = fkc.referred_table
.pythonlibs/lib/python3.11/site-packages/sqlalchemy/sql/schema.py:4751: in referred_table
    return self.elements[0].column.table
.pythonlibs/lib/python3.11/site-packages/sqlalchemy/util/langhelpers.py:1146: in __get__
    obj.__dict__[self.__name__] = result = self.fget(obj)
.pythonlibs/lib/python3.11/site-packages/sqlalchemy/sql/schema.py:3159: in column
    return self._resolve_column()
.pythonlibs/lib/python3.11/site-packages/sqlalchemy/sql/schema.py:3182: in _resolve_column
    raise exc.NoReferencedTableError(
E   sqlalchemy.exc.NoReferencedTableError: Foreign key associated with column 'bonus_transactions.user_id' could not find table 'users' with which to generate a foreign key to target column 'id'
__________________________ ERROR at setup of test_noble_relation_verification ___________________________
.pythonlibs/lib/python3.11/site-packages/pytest_asyncio/plugin.py:304: in _asyncgen_fixture_wrapper
    result = event_loop.run_until_complete(setup())
/nix/store/clx0mcir7qw8zk36zbr4jra789g3knf6-python3-3.11.10/lib/python3.11/asyncio/base_events.py:654: in run_until_complete
    return future.result()
.pythonlibs/lib/python3.11/site-packages/pytest_asyncio/plugin.py:286: in setup
    res = await gen_obj.__anext__()
tests/conftest.py:17: in app
    app = create_app()
app/__init__.py:87: in create_app
    db.drop_all()
.pythonlibs/lib/python3.11/site-packages/flask_sqlalchemy/extension.py:917: in drop_all
    self._call_for_binds(bind_key, "drop_all")
.pythonlibs/lib/python3.11/site-packages/flask_sqlalchemy/extension.py:881: in _call_for_binds
    getattr(metadata, op_name)(bind=engine)
.pythonlibs/lib/python3.11/site-packages/sqlalchemy/sql/schema.py:5856: in drop_all
    bind._run_ddl_visitor(
.pythonlibs/lib/python3.11/site-packages/sqlalchemy/engine/base.py:3243: in _run_ddl_visitor
    conn._run_ddl_visitor(visitorcallable, element, **kwargs)
.pythonlibs/lib/python3.11/site-packages/sqlalchemy/engine/base.py:2447: in _run_ddl_visitor
    visitorcallable(self.dialect, self, **kwargs).traverse_single(element)
.pythonlibs/lib/python3.11/site-packages/sqlalchemy/sql/visitors.py:671: in traverse_single
    return meth(obj, **kw)
.pythonlibs/lib/python3.11/site-packages/sqlalchemy/sql/ddl.py:1022: in visit_metadata
    sort_tables_and_constraints(
.pythonlibs/lib/python3.11/site-packages/sqlalchemy/sql/ddl.py:1327: in sort_tables_and_constraints
    dependent_on = fkc.referred_table
.pythonlibs/lib/python3.11/site-packages/sqlalchemy/sql/schema.py:4751: in referred_table
    return self.elements[0].column.table
.pythonlibs/lib/python3.11/site-packages/sqlalchemy/util/langhelpers.py:1146: in __get__
    obj.__dict__[self.__name__] = result = self.fget(obj)
.pythonlibs/lib/python3.11/site-packages/sqlalchemy/sql/schema.py:3159: in column
    return self._resolve_column()
.pythonlibs/lib/python3.11/site-packages/sqlalchemy/sql/schema.py:3182: in _resolve_column
    raise exc.NoReferencedTableError(
E   sqlalchemy.exc.NoReferencedTableError: Foreign key associated with column 'bonus_transactions.user_id' could not find table 'users' with which to generate a foreign key to target column 'id'
______________________________ ERROR at setup of test_gold_transformation _______________________________
.pythonlibs/lib/python3.11/site-packages/pytest_asyncio/plugin.py:304: in _asyncgen_fixture_wrapper
    result = event_loop.run_until_complete(setup())
/nix/store/clx0mcir7qw8zk36zbr4jra789g3knf6-python3-3.11.10/lib/python3.11/asyncio/base_events.py:654: in run_until_complete
    return future.result()
.pythonlibs/lib/python3.11/site-packages/pytest_asyncio/plugin.py:286: in setup
    res = await gen_obj.__anext__()
tests/conftest.py:17: in app
    app = create_app()
app/__init__.py:87: in create_app
    db.drop_all()
.pythonlibs/lib/python3.11/site-packages/flask_sqlalchemy/extension.py:917: in drop_all
    self._call_for_binds(bind_key, "drop_all")
.pythonlibs/lib/python3.11/site-packages/flask_sqlalchemy/extension.py:881: in _call_for_binds
    getattr(metadata, op_name)(bind=engine)
.pythonlibs/lib/python3.11/site-packages/sqlalchemy/sql/schema.py:5856: in drop_all
    bind._run_ddl_visitor(
.pythonlibs/lib/python3.11/site-packages/sqlalchemy/engine/base.py:3243: in _run_ddl_visitor
    conn._run_ddl_visitor(visitorcallable, element, **kwargs)
.pythonlibs/lib/python3.11/site-packages/sqlalchemy/engine/base.py:2447: in _run_ddl_visitor
    visitorcallable(self.dialect, self, **kwargs).traverse_single(element)
.pythonlibs/lib/python3.11/site-packages/sqlalchemy/sql/visitors.py:671: in traverse_single
    return meth(obj, **kw)
.pythonlibs/lib/python3.11/site-packages/sqlalchemy/sql/ddl.py:1022: in visit_metadata
    sort_tables_and_constraints(
.pythonlibs/lib/python3.11/site-packages/sqlalchemy/sql/ddl.py:1327: in sort_tables_and_constraints
    dependent_on = fkc.referred_table
.pythonlibs/lib/python3.11/site-packages/sqlalchemy/sql/schema.py:4751: in referred_table
    return self.elements[0].column.table
.pythonlibs/lib/python3.11/site-packages/sqlalchemy/util/langhelpers.py:1146: in __get__
    obj.__dict__[self.__name__] = result = self.fget(obj)
.pythonlibs/lib/python3.11/site-packages/sqlalchemy/sql/schema.py:3159: in column
    return self._resolve_column()
.pythonlibs/lib/python3.11/site-packages/sqlalchemy/sql/schema.py:3182: in _resolve_column
    raise exc.NoReferencedTableError(
E   sqlalchemy.exc.NoReferencedTableError: Foreign key associated with column 'bonus_transactions.user_id' could not find table 'users' with which to generate a foreign key to target column 'id'
_________________________ ERROR at setup of test_minimum_transformation_amount __________________________
.pythonlibs/lib/python3.11/site-packages/pytest_asyncio/plugin.py:304: in _asyncgen_fixture_wrapper
    result = event_loop.run_until_complete(setup())
/nix/store/clx0mcir7qw8zk36zbr4jra789g3knf6-python3-3.11.10/lib/python3.11/asyncio/base_events.py:654: in run_until_complete
    return future.result()
.pythonlibs/lib/python3.11/site-packages/pytest_asyncio/plugin.py:286: in setup
    res = await gen_obj.__anext__()
tests/conftest.py:17: in app
    app = create_app()
app/__init__.py:87: in create_app
    db.drop_all()
.pythonlibs/lib/python3.11/site-packages/flask_sqlalchemy/extension.py:917: in drop_all
    self._call_for_binds(bind_key, "drop_all")
.pythonlibs/lib/python3.11/site-packages/flask_sqlalchemy/extension.py:881: in _call_for_binds
    getattr(metadata, op_name)(bind=engine)
.pythonlibs/lib/python3.11/site-packages/sqlalchemy/sql/schema.py:5856: in drop_all
    bind._run_ddl_visitor(
.pythonlibs/lib/python3.11/site-packages/sqlalchemy/engine/base.py:3243: in _run_ddl_visitor
    conn._run_ddl_visitor(visitorcallable, element, **kwargs)
.pythonlibs/lib/python3.11/site-packages/sqlalchemy/engine/base.py:2447: in _run_ddl_visitor
    visitorcallable(self.dialect, self, **kwargs).traverse_single(element)
.pythonlibs/lib/python3.11/site-packages/sqlalchemy/sql/visitors.py:671: in traverse_single
    return meth(obj, **kw)
.pythonlibs/lib/python3.11/site-packages/sqlalchemy/sql/ddl.py:1022: in visit_metadata
    sort_tables_and_constraints(
.pythonlibs/lib/python3.11/site-packages/sqlalchemy/sql/ddl.py:1327: in sort_tables_and_constraints
    dependent_on = fkc.referred_table
.pythonlibs/lib/python3.11/site-packages/sqlalchemy/sql/schema.py:4751: in referred_table
    return self.elements[0].column.table
.pythonlibs/lib/python3.11/site-packages/sqlalchemy/util/langhelpers.py:1146: in __get__
    obj.__dict__[self.__name__] = result = self.fget(obj)
.pythonlibs/lib/python3.11/site-packages/sqlalchemy/sql/schema.py:3159: in column
    return self._resolve_column()
.pythonlibs/lib/python3.11/site-packages/sqlalchemy/sql/schema.py:3182: in _resolve_column
    raise exc.NoReferencedTableError(
E   sqlalchemy.exc.NoReferencedTableError: Foreign key associated with column 'bonus_transactions.user_id' could not find table 'users' with which to generate a foreign key to target column 'id'
======================================== short test summary info ========================================
ERROR tests/test_blockchain.py::test_blockchain_connection - sqlalchemy.exc.NoReferencedTableError: Foreign key associated with column 'bonus_transactions.user_i...
ERROR tests/test_blockchain.py::test_noble_rank_update - sqlalchemy.exc.NoReferencedTableError: Foreign key associated with column 'bonus_transactions.user_i...
ERROR tests/test_noble_system.py::test_noble_rank_creation - sqlalchemy.exc.NoReferencedTableError: Foreign key associated with column 'bonus_transactions.user_i...
ERROR tests/test_noble_system.py::test_noble_relation_verification - sqlalchemy.exc.NoReferencedTableError: Foreign key associated with column 'bonus_transactions.user_i...
ERROR tests/test_transformation.py::test_gold_transformation - sqlalchemy.exc.NoReferencedTableError: Foreign key associated with column 'bonus_transactions.user_i...
ERROR tests/test_transformation.py::test_minimum_transformation_amount - sqlalchemy.exc.NoReferencedTableError: Foreign key associated with column 'bonus_transactions.user_i...
=========================================== 6 errors in 1.71s ===========================================
~/gold-investment-backend$