~/gold-investment-backend$ python -m pytest tests/ -v
========================================== test session starts ===========================================
platform linux -- Python 3.11.10, pytest-7.4.3, pluggy-1.5.0 -- /home/runner/gold-investment-backend/.pythonlibs/bin/python
cachedir: .pytest_cache
rootdir: /home/runner/gold-investment-backend/tests
configfile: pytest.ini
plugins: mock-3.14.0, web3-6.11.4, asyncio-0.21.1
asyncio: mode=Mode.AUTO
collected 38 items / 4 errors                                                                            

================================================= ERRORS =================================================
_____________________________________ ERROR collecting test_auth.py ______________________________________
ImportError while importing test module '/home/runner/gold-investment-backend/tests/test_auth.py'.
Hint: make sure your test modules/packages have valid Python names.
Traceback:
.pythonlibs/lib/python3.11/site-packages/_pytest/python.py:617: in _importtestmodule
    mod = import_path(self.path, mode=importmode, root=self.config.rootpath)
.pythonlibs/lib/python3.11/site-packages/_pytest/pathlib.py:567: in import_path
    importlib.import_module(module_name)
/nix/store/clx0mcir7qw8zk36zbr4jra789g3knf6-python3-3.11.10/lib/python3.11/importlib/__init__.py:126: in import_module
    return _bootstrap._gcd_import(name[level:], package, level)
<frozen importlib._bootstrap>:1204: in _gcd_import
    ???
<frozen importlib._bootstrap>:1176: in _find_and_load
    ???
<frozen importlib._bootstrap>:1147: in _find_and_load_unlocked
    ???
<frozen importlib._bootstrap>:690: in _load_unlocked
    ???
.pythonlibs/lib/python3.11/site-packages/_pytest/assertion/rewrite.py:186: in exec_module
    exec(co, module.__dict__)
tests/test_auth.py:4: in <module>
    from app.models import User, NobleRank, db
E   ImportError: cannot import name 'User' from 'app.models' (/home/runner/gold-investment-backend/app/models/__init__.py)
________________________________ ERROR collecting test_complete_system.py ________________________________
ImportError while importing test module '/home/runner/gold-investment-backend/tests/test_complete_system.py'.
Hint: make sure your test modules/packages have valid Python names.
Traceback:
.pythonlibs/lib/python3.11/site-packages/_pytest/python.py:617: in _importtestmodule
    mod = import_path(self.path, mode=importmode, root=self.config.rootpath)
.pythonlibs/lib/python3.11/site-packages/_pytest/pathlib.py:567: in import_path
    importlib.import_module(module_name)
/nix/store/clx0mcir7qw8zk36zbr4jra789g3knf6-python3-3.11.10/lib/python3.11/importlib/__init__.py:126: in import_module
    return _bootstrap._gcd_import(name[level:], package, level)
<frozen importlib._bootstrap>:1204: in _gcd_import
    ???
<frozen importlib._bootstrap>:1176: in _find_and_load
    ???
<frozen importlib._bootstrap>:1147: in _find_and_load_unlocked
    ???
<frozen importlib._bootstrap>:690: in _load_unlocked
    ???
.pythonlibs/lib/python3.11/site-packages/_pytest/assertion/rewrite.py:186: in exec_module
    exec(co, module.__dict__)
tests/test_complete_system.py:4: in <module>
    from app.models import User, MoneyAccount, GoldAccount
E   ImportError: cannot import name 'User' from 'app.models' (/home/runner/gold-investment-backend/app/models/__init__.py)
_________________________________ ERROR collecting test_noble_system.py __________________________________
ImportError while importing test module '/home/runner/gold-investment-backend/tests/test_noble_system.py'.
Hint: make sure your test modules/packages have valid Python names.
Traceback:
.pythonlibs/lib/python3.11/site-packages/_pytest/python.py:617: in _importtestmodule
    mod = import_path(self.path, mode=importmode, root=self.config.rootpath)
.pythonlibs/lib/python3.11/site-packages/_pytest/pathlib.py:567: in import_path
    importlib.import_module(module_name)
/nix/store/clx0mcir7qw8zk36zbr4jra789g3knf6-python3-3.11.10/lib/python3.11/importlib/__init__.py:126: in import_module
    return _bootstrap._gcd_import(name[level:], package, level)
<frozen importlib._bootstrap>:1204: in _gcd_import
    ???
<frozen importlib._bootstrap>:1176: in _find_and_load
    ???
<frozen importlib._bootstrap>:1147: in _find_and_load_unlocked
    ???
<frozen importlib._bootstrap>:690: in _load_unlocked
    ???
.pythonlibs/lib/python3.11/site-packages/_pytest/assertion/rewrite.py:186: in exec_module
    exec(co, module.__dict__)
tests/test_noble_system.py:4: in <module>
    from app.models import User, NobleRank, Transaction
E   ImportError: cannot import name 'User' from 'app.models' (/home/runner/gold-investment-backend/app/models/__init__.py)
__________________________________ ERROR collecting test_system_flow.py __________________________________
ImportError while importing test module '/home/runner/gold-investment-backend/tests/test_system_flow.py'.
Hint: make sure your test modules/packages have valid Python names.
Traceback:
.pythonlibs/lib/python3.11/site-packages/_pytest/python.py:617: in _importtestmodule
    mod = import_path(self.path, mode=importmode, root=self.config.rootpath)
.pythonlibs/lib/python3.11/site-packages/_pytest/pathlib.py:567: in import_path
    importlib.import_module(module_name)
/nix/store/clx0mcir7qw8zk36zbr4jra789g3knf6-python3-3.11.10/lib/python3.11/importlib/__init__.py:126: in import_module
    return _bootstrap._gcd_import(name[level:], package, level)
<frozen importlib._bootstrap>:1204: in _gcd_import
    ???
<frozen importlib._bootstrap>:1176: in _find_and_load
    ???
<frozen importlib._bootstrap>:1147: in _find_and_load_unlocked
    ???
<frozen importlib._bootstrap>:690: in _load_unlocked
    ???
.pythonlibs/lib/python3.11/site-packages/_pytest/assertion/rewrite.py:186: in exec_module
    exec(co, module.__dict__)
tests/test_system_flow.py:6: in <module>
    from app.models import User, MoneyAccount, GoldAccount, Transaction
E   ImportError: cannot import name 'User' from 'app.models' (/home/runner/gold-investment-backend/app/models/__init__.py)
============================================ warnings summary ============================================
tests/test_rate_limiting.py:56
  /home/runner/gold-investment-backend/tests/test_rate_limiting.py:56: PytestUnknownMarkWarning: Unknown pytest.mark.redis - is this a typo?  You can register custom marks to avoid this warning - for details, see https://docs.pytest.org/en/stable/how-to/mark.html
    @pytest.mark.redis

tests/test_rate_limiting.py:94
  /home/runner/gold-investment-backend/tests/test_rate_limiting.py:94: PytestUnknownMarkWarning: Unknown pytest.mark.redis - is this a typo?  You can register custom marks to avoid this warning - for details, see https://docs.pytest.org/en/stable/how-to/mark.html
    @pytest.mark.redis

tests/test_rate_limiting.py:141
  /home/runner/gold-investment-backend/tests/test_rate_limiting.py:141: PytestUnknownMarkWarning: Unknown pytest.mark.redis - is this a typo?  You can register custom marks to avoid this warning - for details, see https://docs.pytest.org/en/stable/how-to/mark.html
    @pytest.mark.redis

tests/config/test_devices.py:5
  /home/runner/gold-investment-backend/tests/config/test_devices.py:5: PytestCollectionWarning: cannot collect test class 'TestDevice' because it has a __init__ constructor (from: config/test_devices.py)
    @dataclass

-- Docs: https://docs.pytest.org/en/stable/how-to/capture-warnings.html
======================================== short test summary info =========================================
ERROR tests/test_auth.py
ERROR tests/test_complete_system.py
ERROR tests/test_noble_system.py
ERROR tests/test_system_flow.py
!!!!!!!!!!!!!!!!!!!!!!!!!!!!!!!! Interrupted: 4 errors during collection !!!!!!!!!!!!!!!!!!!!!!!!!!!!!!!!!
===================================== 4 warnings, 4 errors in 0.89s ======================================
~/gold-investment-backend$