~/gold-investment-backend$ python -m pytest tests/unit/test_transformation.py -v
========================================== test session starts ===========================================
platform linux -- Python 3.11.10, pytest-8.1.1, pluggy-1.4.0 -- /home/runner/gold-investment-backend/.pythonlibs/bin/python
cachedir: .pytest_cache
rootdir: /home/runner/gold-investment-backend/tests
configfile: pytest.ini
plugins: asyncio-0.23.6, mock-3.14.0, cov-4.1.0, web3-6.11.3
asyncio: mode=Mode.AUTO
collected 1 item                                                                                         

tests/unit/test_transformation.py::test_transformation_calculates_correct_gold_amount FAILED       [100%]

================================================ FAILURES ================================================
___________________________ test_transformation_calculates_correct_gold_amount ___________________________

    @pytest.mark.asyncio
    async def test_transformation_calculates_correct_gold_amount():
        # Arrange
        service = TransformationService()
        euro_amount = Decimal('100.00')
        fixing_price = Decimal('50.00')
        expected_gold = Decimal('1.90')  # (100 - 5% fee) / 50
    
        # Act
        result = await service.process_transformation(1, euro_amount, fixing_price)
    
        # Assert
>       assert result['status'] == 'success'
E       AssertionError: assert 'error' == 'success'
E         
E         - success
E         + error

tests/unit/test_transformation.py:19: AssertionError
------------------------------------------- Captured log call --------------------------------------------
ERROR    app.services.transformation_service:transformation_service.py:30 Error during transformation: Working outside of application context.

This typically means that you attempted to use functionality that needed
the current application. To solve this, set up an application context
with app.app_context(). See the documentation for more information.
======================================== short test summary info =========================================
FAILED tests/unit/test_transformation.py::test_transformation_calculates_correct_gold_amount - AssertionError: assert 'error' == 'success'
===================================== 1 failed, 2 warnings in 0.12s ======================================
~/gold-investment-backend$ ^C
~/gold-investment-backend$ 